Workbook

Sheet All Matches
A1: Match # | B1: Stage | C1: Group | D1: Date | E1: Home Team | F1: Home | G1: Away | H1: Away Team | I1: Notes
A2: 1 | B2: Group stage | C2: A | D2: 2026-06-11 | E2: Mexico | F2: 2 | G2: 0 | H2: South Africa
A3: 2 | B3: Group stage | C3: A | D3: 2026-06-12 | E3: South Korea | F3: 2 | G3: 1 | H3: Czechia
A4: 3 | B4: Group stage | C4: A | D4: 2026-06-18 | E4: Czechia | F4: 1 | G4: 1 | H4: South Africa
A5: 4 | B5: Group stage | C5: A | D5: 2026-06-18 | E5: Mexico | F5: 1 | G5: 0 | H5: South Korea
A6: 5 | B6: Group stage | C6: A | D6: 2026-06-24 | E6: Czechia | F6: 0 | G6: 3 | H6: Mexico
A7: 6 | B7: Group stage | C7: A | D7: 2026-06-24 | E7: South Africa | F7: 1 | G7: 0 | H7: South Korea
A8: 7 | B8: Group stage | C8: B | D8: 2026-06-12 | E8: Canada | F8: 1 | G8: 1 | H8: Bosnia and Herzegovina
A9: 8 | B9: Group stage | C9: B | D9: 2026-06-13 | E9: Qatar | F9: 1 | G9: 1 | H9: Switzerland
A10: 9 | B10: Group stage | C10: B | D10: 2026-06-18 | E10: Switzerland | F10: 4 | G10: 1 | H10: Bosnia and Herzegovina
A11: 10 | B11: Group stage | C11: B | D11: 2026-06-19 | E11: Canada | F11: 6 | G11: 0 | H11: Qatar
A12: 11 | B12: Group stage | C12: B | D12: 2026-06-24 | E12: Switzerland | F12: 2 | G12: 1 | H12: Canada
A13: 12 | B13: Group stage | C13: B | D13: 2026-06-24 | E13: Bosnia and Herzegovina | F13: 3 | G13: 1 | H13: Qatar
... A73: 72 | B73: Group stage | C73: L | D73: 2026-06-27 | E73: Croatia | F73: 2 | G73: 1 | H73: Ghana
A74: 73 | B74: Round of 32 | D74: 2026-06-28 | E74: Canada | F74: 1 | G74: 0 | H74: South Africa
A75: 74 | B75: Round of 32 | D75: 2026-06-29 | E75: Brazil | F75: 2 | G75: 1 | H75: Japan
A76: 75 | B76: Round of 32 | D76: 2026-06-29 | E76: Paraguay | F76: 1 | G76: 1 | H76: Germany | I76: Paraguay won on penalties
A77: 76 | B77: Round of 32 | D77: 2026-06-30 | E77: Morocco | F77: 1 | G77: 1 | H77: Netherlands | I77: Morocco won on penalties
A78: 77 | B78: Round of 32 | D78: 2026-06-30 | E78: Norway | F78: 2 | G78: 1 | H78: Cote d'Ivoire
A79: 78 | B79: Round of 32 | D79: 2026-07-01 | E79: France | F79: 3 | G79: 0 | H79: Sweden
A80: 79 | B80: Round of 32 | D80: 2026-07-01 | E80: Mexico | F80: 2 | G80: 0 | H80: Ecuador
A81: 80 | B81: Round of 32 | D81: 2026-07-01 | E81: England | F81: 2 | G81: 1 | H81: DR Congo
A82: 81 | B82: Round of 32 | D82: 2026-07-02 | E82: Belgium | F82: 3 | G82: 2 | H82: Senegal | I82: Belgium won after extra time
A83: 82 | B83: Round of 32 | D83: 2026-07-02 | E83: USA | F83: 2 | G83: 0 | H83: Bosnia and Herzegovina
A84: 83 | B84: Round of 32 | D84: 2026-07-02 | E84: Spain | F84: 3 | G84: 0 | H84: Austria
A85: 84 | B85: Round of 32 | D85: 2026-07-02 | E85: Portugal | F85: 2 | G85: 1 | H85: Croatia
A86: 85 | B86: Round of 32 | D86: 2026-07-03 | E86: Switzerland | F86: 2 | G86: 0 | H86: Algeria
A87: 86 | B87: Round of 32 | D87: 2026-07-03 | E87: Egypt | F87: 1 | G87: 1 | H87: Australia | I87: Egypt won on penalties
A88: 87 | B88: Round of 32 | D88: 2026-07-03 | E88: Argentina | F88: 3 | G88: 2 | H88: Cabo Verde | I88: Argentina won after extra time
A89: 88 | B89: Round of 32 | D89: 2026-07-03 | E89: Colombia | F89: 1 | G89: 0 | H89: Ghana
A90: 89 | B90: Round of 16 | D90: 2026-07-04 | E90: Morocco | F90: 3 | G90: 0 | H90: Canada
A91: 90 | B91: Round of 16 | D91: 2026-07-04 | E91: France | F91: 1 | G91: 0 | H91: Paraguay
A92: 91 | B92: Round of 16 | D92: 2026-07-05 | E92: Norway | F92: 2 | G92: 1 | H92: Brazil
A93: 92 | B93: Round of 16 | D93: 2026-07-05 | E93: England | F93: 3 | G93: 2 | H93: Mexico
A94: 93 | B94: Round of 16 | D94: 2026-07-06 | E94: Spain | F94: 1 | G94: 0 | H94: Portugal
A95: 94 | B95: Round of 16 | D95: 2026-07-06 | E95: Belgium | F95: 4 | G95: 1 | H95: USA
A96: 95 | B96: Round of 16 | D96: 2026-07-07 | E96: Argentina | F96: 3 | G96: 2 | H96: Egypt
A97: 96 | B97: Round of 16 | D97: 2026-07-07 | E97: Switzerland | F97: 0 | G97: 0 | H97: Colombia | I97: Switzerland won on penalties after extra time
A98: 97 | B98: Quarter-final | D98: 2026-07-09 | E98: France | F98: 2 | G98: 0 | H98: Morocco
A99: 98 | B99: Quarter-final | D99: 2026-07-10 | E99: Spain | F99: 2 | G99: 1 | H99: Belgium
...

Sheet Group Standings
A1: Group | B1: Team | C1: MP | D1: W | E1: D | F1: L | G1: GF | H1: GA | I1: GD | J1: Pts
A2: A | B2: Mexico | C2: =SUMPRODUCT(('All Matches'!$C$2:$C$73=$A2)*((('All Matches'!$E$2:$E$73=$B2)+('All Matches'!$H$2:$H$73=$B2))>0)) -> 3 | D2: =SUMPRODUCT(('All Matches'!$C$2:$C$73=$A2)*((('All Matches'!$E$2:$E$73=$B2)*('All Matches'!$F$2:$F$73>'All Matches'!$G$2:$G$73))+(('All Matches'!$H$2:$H$73=$B2)*('All Matches'!$G$2:$G$73>'All Matches'!$F$2:$F$73)))) -> 3 | E2: =SUMPRODUCT(('All Matches'!$C$2:$C$73=$A2)*((('All Matches'!$E$2:$E$73=$B2)+('All Matches'!$H$2:$H$73=$B2))>0)*('All Matches'!$F$2:$F$73='All Matches'!$G$2:$G$73)) -> 0 | F2: =SUMPRODUCT(('All Matches'!$C$2:$C$73=$A2)*((('All Matches'!$E$2:$E$73=$B2)*('All Matches'!$F$2:$F$73<'All Matches'!$G$2:$G$73))+(('All Matches'!$H$2:$H$73=$B2)*('All Matches'!$G$2:$G$73<'All Matches'!$F$2:$F$73)))) -> 0 | G2: =SUMIFS('All Matches'!$F$2:$F$73,'All Matches'!$C$2:$C$73,$A2,'All Matches'!$E$2:$E$73,$B2)+SUMIFS('All Matches'!$G$2:$G$73,'All Matches'!$C$2:$C$73,$A2,'All Matches'!$H$2:$H$73,$B2) -> 6 | H2: =SUMIFS('All Matches'!$G$2:$G$73,'All Matches'!$C$2:$C$73,$A2,'All Matches'!$E$2:$E$73,$B2)+SUMIFS('All Matches'!$F$2:$F$73,'All Matches'!$C$2:$C$73,$A2,'All Matches'!$H$2:$H$73,$B2) -> 0 | I2: =G2-H2 -> 6 | J2: =3*D2+E2 -> 9
A3: A | B3: South Africa | C3: =SUMPRODUCT(('All Matches'!$C$2:$C$73=$A3)*((('All Matches'!$E$2:$E$73=$B3)+('All Matches'!$H$2:$H$73=$B3))>0)) -> 3 | D3: =SUMPRODUCT(('All Matches'!$C$2:$C$73=$A3)*((('All Matches'!$E$2:$E$73=$B3)*('All Matches'!$F$2:$F$73>'All Matches'!$G$2:$G$73))+(('All Matches'!$H$2:$H$73=$B3)*('All Matches'!$G$2:$G$73>'All Matches'!$F$2:$F$73)))) -> 1 | E3: =SUMPRODUCT(('All Matches'!$C$2:$C$73=$A3)*((('All Matches'!$E$2:$E$73=$B3)+('All Matches'!$H$2:$H$73=$B3))>0)*('All Matches'!$F$2:$F$73='All Matches'!$G$2:$G$73)) -> 1 | F3: =SUMPRODUCT(('All Matches'!$C$2:$C$73=$A3)*((('All Matches'!$E$2:$E$73=$B3)*('All Matches'!$F$2:$F$73<'All Matches'!$G$2:$G$73))+(('All Matches'!$H$2:$H$73=$B3)*('All Matches'!$G$2:$G$73<'All Matches'!$F$2:$F$73)))) -> 1 | G3: =SUMIFS('All Matches'!$F$2:$F$73,'All Matches'!$C$2:$C$73,$A3,'All Matches'!$E$2:$E$73,$B3)+SUMIFS('All Matches'!$G$2:$G$73,'All Matches'!$C$2:$C$73,$A3,'All Matches'!$H$2:$H$73,$B3) -> 2 | H3: =SUMIFS('All Matches'!$G$2:$G$73,'All Matches'!$C$2:$C$73,$A3,'All Matches'!$E$2:$E$73,$B3)+SUMIFS('All Matches'!$F$2:$F$73,'All Matches'!$C$2:$C$73,$A3,'All Matches'!$H$2:$H$73,$B3) -> 3 | I3: =G3-H3 -> -1 | J3: =3*D3+E3 -> 4
A4: A | B4: South Korea | C4: =SUMPRODUCT(('All Matches'!$C$2:$C$73=$A4)*((('All Matches'!$E$2:$E$73=$B4)+('All Matches'!$H$2:$H$73=$B4))>0)) -> 3 | D4: =SUMPRODUCT(('All Matches'!$C$2:$C$73=$A4)*((('All Matches'!$E$2:$E$73=$B4)*('All Matches'!$F$2:$F$73>'All Matches'!$G$2:$G$73))+(('All Matches'!$H$2:$H$73=$B4)*('All Matches'!$G$2:$G$73>'All Matches'!$F$2:$F$73)))) -> 1 | E4: =SUMPRODUCT(('All Matches'!$C$2:$C$73=$A4)*((('All Matches'!$E$2:$E$73=$B4)+('All Matches'!$H$2:$H$73=$B4))>0)*('All Matches'!$F$2:$F$73='All Matches'!$G$2:$G$73)) -> 0 | F4: =SUMPRODUCT(('All Matches'!$C$2:$C$73=$A4)*((('All Matches'!$E$2:$E$73=$B4)*('All Matches'!$F$2:$F$73<'All Matches'!$G$2:$G$73))+(('All Matches'!$H$2:$H$73=$B4)*('All Matches'!$G$2:$G$73<'All Matches'!$F$2:$F$73)))) -> 2 | G4: =SUMIFS('All Matches'!$F$2:$F$73,'All Matches'!$C$2:$C$73,$A4,'All Matches'!$E$2:$E$73,$B4)+SUMIFS('All Matches'!$G$2:$G$73,'All Matches'!$C$2:$C$73,$A4,'All Matches'!$H$2:$H$73,$B4) -> 2 | H4: =SUMIFS('All Matches'!$G$2:$G$73,'All Matches'!$C$2:$C$73,$A4,'All Matches'!$E$2:$E$73,$B4)+SUMIFS('All Matches'!$F$2:$F$73,'All Matches'!$C$2:$C$73,$A4,'All Matches'!$H$2:$H$73,$B4) -> 3 | I4: =G4-H4 -> -1 | J4: =3*D4+E4 -> 3
A5: A | B5: Czechia | C5: =SUMPRODUCT(('All Matches'!$C$2:$C$73=$A5)*((('All Matches'!$E$2:$E$73=$B5)+('All Matches'!$H$2:$H$73=$B5))>0)) -> 3 | D5: =SUMPRODUCT(('All Matches'!$C$2:$C$73=$A5)*((('All Matches'!$E$2:$E$73=$B5)*('All Matches'!$F$2:$F$73>'All Matches'!$G$2:$G$73))+(('All Matches'!$H$2:$H$73=$B5)*('All Matches'!$G$2:$G$73>'All Matches'!$F$2:$F$73)))) -> 0 | E5: =SUMPRODUCT(('All Matches'!$C$2:$C$73=$A5)*((('All Matches'!$E$2:$E$73=$B5)+('All Matches'!$H$2:$H$73=$B5))>0)*('All Matches'!$F$2:$F$73='All Matches'!$G$2:$G$73)) -> 1 | F5: =SUMPRODUCT(('All Matches'!$C$2:$C$73=$A5)*((('All Matches'!$E$2:$E$73=$B5)*('All Matches'!$F$2:$F$73<'All Matches'!$G$2:$G$73))+(('All Matches'!$H$2:$H$73=$B5)*('All Matches'!$G$2:$G$73<'All Matches'!$F$2:$F$73)))) -> 2 | G5: =SUMIFS('All Matches'!$F$2:$F$73,'All Matches'!$C$2:$C$73,$A5,'All Matches'!$E$2:$E$73,$B5)+SUMIFS('All Matches'!$G$2:$G$73,'All Matches'!$C$2:$C$73,$A5,'All Matches'!$H$2:$H$73,$B5) -> 2 | H5: =SUMIFS('All Matches'!$G$2:$G$73,'All Matches'!$C$2:$C$73,$A5,'All Matches'!$E$2:$E$73,$B5)+SUMIFS('All Matches'!$F$2:$F$73,'All Matches'!$C$2:$C$73,$A5,'All Matches'!$H$2:$H$73,$B5) -> 6 | I5: =G5-H5 -> -4 | J5: =3*D5+E5 -> 1
A7: B | B7: Canada | C7: =SUMPRODUCT(('All Matches'!$C$2:$C$73=$A7)*((('All Matches'!$E$2:$E$73=$B7)+('All Matches'!$H$2:$H$73=$B7))>0)) -> 3 | D7: =SUMPRODUCT(('All Matches'!$C$2:$C$73=$A7)*((('All Matches'!$E$2:$E$73=$B7)*('All Matches'!$F$2:$F$73>'All Matches'!$G$2:$G$73))+(('All Matches'!$H$2:$H$73=$B7)*('All Matches'!$G$2:$G$73>'All Matches'!$F$2:$F$73)))) -> 1 | E7: =SUMPRODUCT(('All Matches'!$C$2:$C$73=$A7)*((('All Matches'!$E$2:$E$73=$B7)+('All Matches'!$H$2:$H$73=$B7))>0)*('All Matches'!$F$2:$F$73='All Matches'!$G$2:$G$73)) -> 1 | F7: =SUMPRODUCT(('All Matches'!$C$2:$C$73=$A7)*((('All Matches'!$E$2:$E$73=$B7)*('All Matches'!$F$2:$F$73<'All Matches'!$G$2:$G$73))+(('All Matches'!$H$2:$H$73=$B7)*('All Matches'!$G$2:$G$73<'All Matches'!$F$2:$F$73)))) -> 1 | G7: =SUMIFS('All Matches'!$F$2:$F$73,'All Matches'!$C$2:$C$73,$A7,'All Matches'!$E$2:$E$73,$B7)+SUMIFS('All Matches'!$G$2:$G$73,'All Matches'!$C$2:$C$73,$A7,'All Matches'!$H$2:$H$73,$B7) -> 8 | H7: =SUMIFS('All Matches'!$G$2:$G$73,'All Matches'!$C$2:$C$73,$A7,'All Matches'!$E$2:$E$73,$B7)+SUMIFS('All Matches'!$F$2:$F$73,'All Matches'!$C$2:$C$73,$A7,'All Matches'!$H$2:$H$73,$B7) -> 3 | I7: =G7-H7 -> 5 | J7: =3*D7+E7 -> 4
A8: B | B8: Bosnia and Herzegovina | C8: =SUMPRODUCT(('All Matches'!$C$2:$C$73=$A8)*((('All Matches'!$E$2:$E$73=$B8)+('All Matches'!$H$2:$H$73=$B8))>0)) -> 3 | D8: =SUMPRODUCT(('All Matches'!$C$2:$C$73=$A8)*((('All Matches'!$E$2:$E$73=$B8)*('All Matches'!$F$2:$F$73>'All Matches'!$G$2:$G$73))+(('All Matches'!$H$2:$H$73=$B8)*('All Matches'!$G$2:$G$73>'All Matches'!$F$2:$F$73)))) -> 1 | E8: =SUMPRODUCT(('All Matches'!$C$2:$C$73=$A8)*((('All Matches'!$E$2:$E$73=$B8)+('All Matches'!$H$2:$H$73=$B8))>0)*('All Matches'!$F$2:$F$73='All Matches'!$G$2:$G$73)) -> 1 | F8: =SUMPRODUCT(('All Matches'!$C$2:$C$73=$A8)*((('All Matches'!$E$2:$E$73=$B8)*('All Matches'!$F$2:$F$73<'All Matches'!$G$2:$G$73))+(('All Matches'!$H$2:$H$73=$B8)*('All Matches'!$G$2:$G$73<'All Matches'!$F$2:$F$73)))) -> 1 | G8: =SUMIFS('All Matches'!$F$2:$F$73,'All Matches'!$C$2:$C$73,$A8,'All Matches'!$E$2:$E$73,$B8)+SUMIFS('All Matches'!$G$2:$G$73,'All Matches'!$C$2:$C$73,$A8,'All Matches'!$H$2:$H$73,$B8) -> 5 | H8: =SUMIFS('All Matches'!$G$2:$G$73,'All Matches'!$C$2:$C$73,$A8,'All Matches'!$E$2:$E$73,$B8)+SUMIFS('All Matches'!$F$2:$F$73,'All Matches'!$C$2:$C$73,$A8,'All Matches'!$H$2:$H$73,$B8) -> 6 | I8: =G8-H8 -> -1 | J8: =3*D8+E8 -> 4
A9: B | B9: Qatar | C9: =SUMPRODUCT(('All Matches'!$C$2:$C$73=$A9)*((('All Matches'!$E$2:$E$73=$B9)+('All Matches'!$H$2:$H$73=$B9))>0)) -> 3 | D9: =SUMPRODUCT(('All Matches'!$C$2:$C$73=$A9)*((('All Matches'!$E$2:$E$73=$B9)*('All Matches'!$F$2:$F$73>'All Matches'!$G$2:$G$73))+(('All Matches'!$H$2:$H$73=$B9)*('All Matches'!$G$2:$G$73>'All Matches'!$F$2:$F$73)))) -> 0 | E9: =SUMPRODUCT(('All Matches'!$C$2:$C$73=$A9)*((('All Matches'!$E$2:$E$73=$B9)+('All Matches'!$H$2:$H$73=$B9))>0)*('All Matches'!$F$2:$F$73='All Matches'!$G$2:$G$73)) -> 1 | F9: =SUMPRODUCT(('All Matches'!$C$2:$C$73=$A9)*((('All Matches'!$E$2:$E$73=$B9)*('All Matches'!$F$2:$F$73<'All Matches'!$G$2:$G$73))+(('All Matches'!$H$2:$H$73=$B9)*('All Matches'!$G$2:$G$73<'All Matches'!$F$2:$F$73)))) -> 2 | G9: =SUMIFS('All Matches'!$F$2:$F$73,'All Matches'!$C$2:$C$73,$A9,'All Matches'!$E$2:$E$73,$B9)+SUMIFS('All Matches'!$G$2:$G$73,'All Matches'!$C$2:$C$73,$A9,'All Matches'!$H$2:$H$73,$B9) -> 2 | H9: =SUMIFS('All Matches'!$G$2:$G$73,'All Matches'!$C$2:$C$73,$A9,'All Matches'!$E$2:$E$73,$B9)+SUMIFS('All Matches'!$F$2:$F$73,'All Matches'!$C$2:$C$73,$A9,'All Matches'!$H$2:$H$73,$B9) -> 10 | I9: =G9-H9 -> -8 | J9: =3*D9+E9 -> 1
A10: B | B10: Switzerland | C10: =SUMPRODUCT(('All Matches'!$C$2:$C$73=$A10)*((('All Matches'!$E$2:$E$73=$B10)+('All Matches'!$H$2:$H$73=$B10))>0)) -> 3 | D10: =SUMPRODUCT(('All Matches'!$C$2:$C$73=$A10)*((('All Matches'!$E$2:$E$73=$B10)*('All Matches'!$F$2:$F$73>'All Matches'!$G$2:$G$73))+(('All Matches'!$H$2:$H$73=$B10)*('All Matches'!$G$2:$G$73>'All Matches'!$F$2:$F$73)))) -> 2 | E10: =SUMPRODUCT(('All Matches'!$C$2:$C$73=$A10)*((('All Matches'!$E$2:$E$73=$B10)+('All Matches'!$H$2:$H$73=$B10))>0)*('All Matches'!$F$2:$F$73='All Matches'!$G$2:$G$73)) -> 1 | F10: =SUMPRODUCT(('All Matches'!$C$2:$C$73=$A10)*((('All Matches'!$E$2:$E$73=$B10)*('All Matches'!$F$2:$F$73<'All Matches'!$G$2:$G$73))+(('All Matches'!$H$2:$H$73=$B10)*('All Matches'!$G$2:$G$73<'All Matches'!$F$2:$F$73)))) -> 0 | G10: =SUMIFS('All Matches'!$F$2:$F$73,'All Matches'!$C$2:$C$73,$A10,'All Matches'!$E$2:$E$73,$B10)+SUMIFS('All Matches'!$G$2:$G$73,'All Matches'!$C$2:$C$73,$A10,'All Matches'!$H$2:$H$73,$B10) -> 7 | H10: =SUMIFS('All Matches'!$G$2:$G$73,'All Matches'!$C$2:$C$73,$A10,'All Matches'!$E$2:$E$73,$B10)+SUMIFS('All Matches'!$F$2:$F$73,'All Matches'!$C$2:$C$73,$A10,'All Matches'!$H$2:$H$73,$B10) -> 3 | I10: =G10-H10 -> 4 | J10: =3*D10+E10 -> 7
A12: C | B12: Brazil | C12: =SUMPRODUCT(('All Matches'!$C$2:$C$73=$A12)*((('All Matches'!$E$2:$E$73=$B12)+('All Matches'!$H$2:$H$73=$B12))>0)) -> 3 | D12: =SUMPRODUCT(('All Matches'!$C$2:$C$73=$A12)*((('All Matches'!$E$2:$E$73=$B12)*('All Matches'!$F$2:$F$73>'All Matches'!$G$2:$G$73))+(('All Matches'!$H$2:$H$73=$B12)*('All Matches'!$G$2:$G$73>'All Matches'!$F$2:$F$73)))) -> 2 | E12: =SUMPRODUCT(('All Matches'!$C$2:$C$73=$A12)*((('All Matches'!$E$2:$E$73=$B12)+('All Matches'!$H$2:$H$73=$B12))>0)*('All Matches'!$F$2:$F$73='All Matches'!$G$2:$G$73)) -> 1 | F12: =SUMPRODUCT(('All Matches'!$C$2:$C$73=$A12)*((('All Matches'!$E$2:$E$73=$B12)*('All Matches'!$F$2:$F$73<'All Matches'!$G$2:$G$73))+(('All Matches'!$H$2:$H$73=$B12)*('All Matches'!$G$2:$G$73<'All Matches'!$F$2:$F$73)))) -> 0 | G12: =SUMIFS('All Matches'!$F$2:$F$73,'All Matches'!$C$2:$C$73,$A12,'All Matches'!$E$2:$E$73,$B12)+SUMIFS('All Matches'!$G$2:$G$73,'All Matches'!$C$2:$C$73,$A12,'All Matches'!$H$2:$H$73,$B12) -> 7 | H12: =SUMIFS('All Matches'!$G$2:$G$73,'All Matches'!$C$2:$C$73,$A12,'All Matches'!$E$2:$E$73,$B12)+SUMIFS('All Matches'!$F$2:$F$73,'All Matches'!$C$2:$C$73,$A12,'All Matches'!$H$2:$H$73,$B12) -> 1 | I12: =G12-H12 -> 6 | J12: =3*D12+E12 -> 7
A13: C | B13: Morocco | C13: =SUMPRODUCT(('All Matches'!$C$2:$C$73=$A13)*((('All Matches'!$E$2:$E$73=$B13)+('All Matches'!$H$2:$H$73=$B13))>0)) -> 3 | D13: =SUMPRODUCT(('All Matches'!$C$2:$C$73=$A13)*((('All Matches'!$E$2:$E$73=$B13)*('All Matches'!$F$2:$F$73>'All Matches'!$G$2:$G$73))+(('All Matches'!$H$2:$H$73=$B13)*('All Matches'!$G$2:$G$73>'All Matches'!$F$2:$F$73)))) -> 2 | E13: =SUMPRODUCT(('All Matches'!$C$2:$C$73=$A13)*((('All Matches'!$E$2:$E$73=$B13)+('All Matches'!$H$2:$H$73=$B13))>0)*('All Matches'!$F$2:$F$73='All Matches'!$G$2:$G$73)) -> 1 | F13: =SUMPRODUCT(('All Matches'!$C$2:$C$73=$A13)*((('All Matches'!$E$2:$E$73=$B13)*('All Matches'!$F$2:$F$73<'All Matches'!$G$2:$G$73))+(('All Matches'!$H$2:$H$73=$B13)*('All Matches'!$G$2:$G$73<'All Matches'!$F$2:$F$73)))) -> 0 | G13: =SUMIFS('All Matches'!$F$2:$F$73,'All Matches'!$C$2:$C$73,$A13,'All Matches'!$E$2:$E$73,$B13)+SUMIFS('All Matches'!$G$2:$G$73,'All Matches'!$C$2:$C$73,$A13,'All Matches'!$H$2:$H$73,$B13) -> 6 | H13: =SUMIFS('All Matches'!$G$2:$G$73,'All Matches'!$C$2:$C$73,$A13,'All Matches'!$E$2:$E$73,$B13)+SUMIFS('All Matches'!$F$2:$F$73,'All Matches'!$C$2:$C$73,$A13,'All Matches'!$H$2:$H$73,$B13) -> 3 | I13: =G13-H13 -> 3 | J13: =3*D13+E13 -> 7
A14: C | B14: Haiti | C14: =SUMPRODUCT(('All Matches'!$C$2:$C$73=$A14)*((('All Matches'!$E$2:$E$73=$B14)+('All Matches'!$H$2:$H$73=$B14))>0)) -> 3 | D14: =SUMPRODUCT(('All Matches'!$C$2:$C$73=$A14)*((('All Matches'!$E$2:$E$73=$B14)*('All Matches'!$F$2:$F$73>'All Matches'!$G$2:$G$73))+(('All Matches'!$H$2:$H$73=$B14)*('All Matches'!$G$2:$G$73>'All Matches'!$F$2:$F$73)))) -> 0 | E14: =SUMPRODUCT(('All Matches'!$C$2:$C$73=$A14)*((('All Matches'!$E$2:$E$73=$B14)+('All Matches'!$H$2:$H$73=$B14))>0)*('All Matches'!$F$2:$F$73='All Matches'!$G$2:$G$73)) -> 0 | F14: =SUMPRODUCT(('All Matches'!$C$2:$C$73=$A14)*((('All Matches'!$E$2:$E$73=$B14)*('All Matches'!$F$2:$F$73<'All Matches'!$G$2:$G$73))+(('All Matches'!$H$2:$H$73=$B14)*('All Matches'!$G$2:$G$73<'All Matches'!$F$2:$F$73)))) -> 3 | G14: =SUMIFS('All Matches'!$F$2:$F$73,'All Matches'!$C$2:$C$73,$A14,'All Matches'!$E$2:$E$73,$B14)+SUMIFS('All Matches'!$G$2:$G$73,'All Matches'!$C$2:$C$73,$A14,'All Matches'!$H$2:$H$73,$B14) -> 2 | H14: =SUMIFS('All Matches'!$G$2:$G$73,'All Matches'!$C$2:$C$73,$A14,'All Matches'!$E$2:$E$73,$B14)+SUMIFS('All Matches'!$F$2:$F$73,'All Matches'!$C$2:$C$73,$A14,'All Matches'!$H$2:$H$73,$B14) -> 8 | I14: =G14-H14 -> -6 | J14: =3*D14+E14 -> 0
A15: C | B15: Scotland | C15: =SUMPRODUCT(('All Matches'!$C$2:$C$73=$A15)*((('All Matches'!$E$2:$E$73=$B15)+('All Matches'!$H$2:$H$73=$B15))>0)) -> 3 | D15: =SUMPRODUCT(('All Matches'!$C$2:$C$73=$A15)*((('All Matches'!$E$2:$E$73=$B15)*('All Matches'!$F$2:$F$73>'All Matches'!$G$2:$G$73))+(('All Matches'!$H$2:$H$73=$B15)*('All Matches'!$G$2:$G$73>'All Matches'!$F$2:$F$73)))) -> 1 | E15: =SUMPRODUCT(('All Matches'!$C$2:$C$73=$A15)*((('All Matches'!$E$2:$E$73=$B15)+('All Matches'!$H$2:$H$73=$B15))>0)*('All Matches'!$F$2:$F$73='All Matches'!$G$2:$G$73)) -> 0 | F15: =SUMPRODUCT(('All Matches'!$C$2:$C$73=$A15)*((('All Matches'!$E$2:$E$73=$B15)*('All Matches'!$F$2:$F$73<'All Matches'!$G$2:$G$73))+(('All Matches'!$H$2:$H$73=$B15)*('All Matches'!$G$2:$G$73<'All Matches'!$F$2:$F$73)))) -> 2 | G15: =SUMIFS('All Matches'!$F$2:$F$73,'All Matches'!$C$2:$C$73,$A15,'All Matches'!$E$2:$E$73,$B15)+SUMIFS('All Matches'!$G$2:$G$73,'All Matches'!$C$2:$C$73,$A15,'All Matches'!$H$2:$H$73,$B15) -> 1 | H15: =SUMIFS('All Matches'!$G$2:$G$73,'All Matches'!$C$2:$C$73,$A15,'All Matches'!$E$2:$E$73,$B15)+SUMIFS('All Matches'!$F$2:$F$73,'All Matches'!$C$2:$C$73,$A15,'All Matches'!$H$2:$H$73,$B15) -> 4 | I15: =G15-H15 -> -3 | J15: =3*D15+E15 -> 3
... A60: L | B60: Panama | C60: =SUMPRODUCT(('All Matches'!$C$2:$C$73=$A60)*((('All Matches'!$E$2:$E$73=$B60)+('All Matches'!$H$2:$H$73=$B60))>0)) -> 3 | D60: =SUMPRODUCT(('All Matches'!$C$2:$C$73=$A60)*((('All Matches'!$E$2:$E$73=$B60)*('All Matches'!$F$2:$F$73>'All Matches'!$G$2:$G$73))+(('All Matches'!$H$2:$H$73=$B60)*('All Matches'!$G$2:$G$73>'All Matches'!$F$2:$F$73)))) -> 0 | E60: =SUMPRODUCT(('All Matches'!$C$2:$C$73=$A60)*((('All Matches'!$E$2:$E$73=$B60)+('All Matches'!$H$2:$H$73=$B60))>0)*('All Matches'!$F$2:$F$73='All Matches'!$G$2:$G$73)) -> 0 | F60: =SUMPRODUCT(('All Matches'!$C$2:$C$73=$A60)*((('All Matches'!$E$2:$E$73=$B60)*('All Matches'!$F$2:$F$73<'All Matches'!$G$2:$G$73))+(('All Matches'!$H$2:$H$73=$B60)*('All Matches'!$G$2:$G$73<'All Matches'!$F$2:$F$73)))) -> 3 | G60: =SUMIFS('All Matches'!$F$2:$F$73,'All Matches'!$C$2:$C$73,$A60,'All Matches'!$E$2:$E$73,$B60)+SUMIFS('All Matches'!$G$2:$G$73,'All Matches'!$C$2:$C$73,$A60,'All Matches'!$H$2:$H$73,$B60) -> 0 | H60: =SUMIFS('All Matches'!$G$2:$G$73,'All Matches'!$C$2:$C$73,$A60,'All Matches'!$E$2:$E$73,$B60)+SUMIFS('All Matches'!$F$2:$F$73,'All Matches'!$C$2:$C$73,$A60,'All Matches'!$H$2:$H$73,$B60) -> 4 | I60: =G60-H60 -> -4 | J60: =3*D60+E60 -> 0

Sheet Knockout Bracket
A1: Stage | B1: Date | C1: Home | D1: Score | E1: Away | F1: Notes
A2: Round of 32 | B2: 2026-06-28 | C2: Canada | D2: 1-0 | E2: South Africa
A3: Round of 32 | B3: 2026-06-29 | C3: Brazil | D3: 2-1 | E3: Japan
A4: Round of 32 | B4: 2026-06-29 | C4: Paraguay | D4: 1-1 | E4: Germany | F4: Paraguay won on penalties
A5: Round of 32 | B5: 2026-06-30 | C5: Morocco | D5: 1-1 | E5: Netherlands | F5: Morocco won on penalties
A6: Round of 32 | B6: 2026-06-30 | C6: Norway | D6: 2-1 | E6: Cote d'Ivoire
A7: Round of 32 | B7: 2026-07-01 | C7: France | D7: 3-0 | E7: Sweden
A8: Round of 32 | B8: 2026-07-01 | C8: Mexico | D8: 2-0 | E8: Ecuador
A9: Round of 32 | B9: 2026-07-01 | C9: England | D9: 2-1 | E9: DR Congo
A10: Round of 32 | B10: 2026-07-02 | C10: Belgium | D10: 3-2 | E10: Senegal | F10: Belgium won after extra time
A11: Round of 32 | B11: 2026-07-02 | C11: USA | D11: 2-0 | E11: Bosnia and Herzegovina
A12: Round of 32 | B12: 2026-07-02 | C12: Spain | D12: 3-0 | E12: Austria
A13: Round of 32 | B13: 2026-07-02 | C13: Portugal | D13: 2-1 | E13: Croatia
A14: Round of 32 | B14: 2026-07-03 | C14: Switzerland | D14: 2-0 | E14: Algeria
A15: Round of 32 | B15: 2026-07-03 | C15: Egypt | D15: 1-1 | E15: Australia | F15: Egypt won on penalties
A16: Round of 32 | B16: 2026-07-03 | C16: Argentina | D16: 3-2 | E16: Cabo Verde | F16: Argentina won after extra time
A17: Round of 32 | B17: 2026-07-03 | C17: Colombia | D17: 1-0 | E17: Ghana
A18: Round of 16 | B18: 2026-07-04 | C18: Morocco | D18: 3-0 | E18: Canada
A19: Round of 16 | B19: 2026-07-04 | C19: France | D19: 1-0 | E19: Paraguay
A20: Round of 16 | B20: 2026-07-05 | C20: Norway | D20: 2-1 | E20: Brazil
A21: Round of 16 | B21: 2026-07-05 | C21: England | D21: 3-2 | E21: Mexico
A22: Round of 16 | B22: 2026-07-06 | C22: Spain | D22: 1-0 | E22: Portugal
A23: Round of 16 | B23: 2026-07-06 | C23: Belgium | D23: 4-1 | E23: USA
A24: Round of 16 | B24: 2026-07-07 | C24: Argentina | D24: 3-2 | E24: Egypt
A25: Round of 16 | B25: 2026-07-07 | C25: Switzerland | D25: 0-0 | E25: Colombia | F25: Switzerland won on penalties after extra time
A26: Quarter-final | B26: 2026-07-09 | C26: France | D26: 2-0 | E26: Morocco
A27: Quarter-final | B27: 2026-07-10 | C27: Spain | D27: 2-1 | E27: Belgium
A28: Quarter-final | B28: 2026-07-10 | C28: England | D28: 2-1 | E28: Norway | F28: England won after extra time
A29: Quarter-final | B29: 2026-07-11 | C29: Argentina | D29: 3-1 | E29: Switzerland | F29: Argentina won after extra time
A30: Semi-final | B30: 2026-07-14 | C30: Spain | D30: 2-0 | E30: France
A31: Semi-final | B31: 2026-07-15 | C31: Argentina | D31: 2-1 | E31: England
A32: Third-place match | B32: 2026-07-18 | C32: England | D32: 6-4 | E32: France
A33: Final | B33: 2026-07-19 | C33: Spain | D33: 1-0 | E33: Argentina | F33: Spain won after extra time

Sheet Sources & Methodology
A1: 2026 FIFA World Cup — Full Match Dataset (104 matches)
A3: Scope: all 104 matches of the 2026 FIFA World Cup (48-team format) — 72 group-stage matches across Groups A-L, plus the 32-match knockout bracket (Round of 32, Round of 16, Quarter-finals, Semi-finals, Third-place match, Final).
A5: Sources:
A6: - Knockout stage results (Round of 32 through Final): FBref.com, World Cup Scores & Fixtures / knockout bracket page.
A7: - Group stage results: individual Wikipedia group pages (2026 FIFA World Cup Group A ... Group L), cross-checked.
A9: Verification method:
A10: - Every group's 6 match scores were checked arithmetically against that group's official final standings (Played/Won/Drawn/Lost/GF/GA/Pts) from FBref's League Table.
A11: - Any match whose score produced a standings mismatch was re-verified with an independent live web search (news wire / match report) and corrected. Corrections made during verification: Group B (Switzerland 4-1 Bosnia, not 5-0; Switzerland 2-1 Canada, not 1-0), Group D (Turkey 3-2 USA, not 1-0), Group E (Germany 2-1 Ivory Coast confirmed; Ecuador 2-1 Germany, not 1-2; Ecuador 0-0 Curacao, not 1-1), Group F (Sweden 5-1 Tunisia, not 5-0; Tunisia 0-4 Japan, not 0-5; Tunisia 1-3 Netherlands, not 1-4), Group G (New Zealand 1-3 Egypt, not 1-2), Group H (Spain 4-0 Saudi Arabia, not 5-0; Cabo Verde 0-0 Saudi Arabia, not 0-1), Group I (Norway 1-4 France, not 0-10; Norway 3-2 Senegal, not 4-2), Group J (Austria 3-1 Jordan, not 2-1), Group K (Portugal 5-0 Uzbekistan, not 6-0), Group L (Croatia 2-1 Ghana, not 1-0).
A12: - After correction, every team's recomputed MP/W/D/L/GF/GA/Pts matches the official standings exactly (see 'Group Standings' tab, which recomputes these live from the match list with formulas).
A14: How to use this workbook:
A15: - 'All Matches' — the full 104-match schedule, filterable by Stage/Group/Date.
A16: - 'Group Standings' — live formulas (SUMPRODUCT/SUMIFS) recompute each team's table row directly from 'All Matches'; edit a score there and the standings update automatically.
A17: - 'Knockout Bracket' — the 32 knockout matches in bracket order with extra-time/penalty notes.

Sheet LR2.1 Dataset
A1: Match # | B1: Stage | C1: Group | D1: Date | E1: Home | F1: Away | G1: Home Score | H1: Away Score | I1: Goal Difference (Target) | J1: X1 FIFA Rank Diff (Away-Home) | K1: X2 Squad Value Diff EURm (Home-Away) | L1: X3 Squad Age Diff (Home-Away) | M1: X4 Prior WC Best Result Diff (Home-Away) | N1: X5 Qualifying GD Diff (Home-Away) | O1: X6 Host Advantage Diff (Home-Away) | P1: X7 Confederation Strength Diff (Home-Away) | Q1: X8 Rest Days Diff (Home-Away) | R1: Home FIFA Rank | S1: Away FIFA Rank | T1: Home Squad Value EURm | U1: Away Squad Value EURm | V1: Home Squad Age | W1: Away Squad Age | X1: Home Prior-WC-Best (ordinal) | Y1: Away Prior-WC-Best (ordinal) | Z1: Home Qualifying GD | AA1: Away Qualifying GD | AB1: Home Confederation | AC1: Away Confederation | AD1: Home Rest Days | AE1: Away Rest Days
A2: 1 | B2: Group stage | C2: A | D2: 2026-06-11 | E2: Mexico | F2: South Africa | G2: 2 | H2: 0 | I2: 2 | J2: 46 | K2: 142.6 | L2: 1.15 | M2: 2 | N2: -6 | O2: 1 | P2: -1 | Q2: 0 | R2: 14 | S2: 60 | T2: 191.85 | U2: 49.25 | V2: 27.5 | W2: 26.35 | X2: 4 | Y2: 2 | Z2: 0 | AA2: 6 | AB2: CONCACAF | AC2: CAF | AD2: 14 | AE2: 14
A3: 2 | B3: Group stage | C3: A | D3: 2026-06-12 | E3: South Korea | F3: Czechia | G3: 2 | H3: 1 | I3: 1 | J3: 15 | K3: -49.13 | L3: 0.23 | M3: -2 | N3: 3 | O3: 0 | P3: -4 | Q3: 0 | R3: 25 | S3: 40 | T3: 139.05 | U3: 188.18 | V3: 27.46 | W3: 27.23 | X3: 5 | Y3: 7 | Z3: 13 | AA3: 10 | AB3: AFC | AC3: UEFA | AD3: 14 | AE3: 14
A4: 3 | B4: Group stage | C4: A | D4: 2026-06-18 | E4: Czechia | F4: South Africa | G4: 1 | H4: 1 | I4: 0 | J4: 20 | K4: 138.93 | L4: 0.88 | M4: 5 | N4: 4 | O4: 0 | P4: 2 | Q4: -1 | R4: 40 | S4: 60 | T4: 188.18 | U4: 49.25 | V4: 27.23 | W4: 26.35 | X4: 7 | Y4: 2 | Z4: 10 | AA4: 6 | AB4: UEFA | AC4: CAF | AD4: 6 | AE4: 7
A5: 4 | B5: Group stage | C5: A | D5: 2026-06-18 | E5: Mexico | F5: South Korea | G5: 1 | H5: 0 | I5: 1 | J5: 11 | K5: 52.8 | L5: 0.04 | M5: -1 | N5: -13 | O5: 1 | P5: 1 | Q5: 1 | R5: 14 | S5: 25 | T5: 191.85 | U5: 139.05 | V5: 27.5 | W5: 27.46 | X5: 4 | Y5: 5 | Z5: 0 | AA5: 13 | AB5: CONCACAF | AC5: AFC | AD5: 7 | AE5: 6
A6: 5 | B6: Group stage | C6: A | D6: 2026-06-24 | E6: Czechia | F6: Mexico | G6: 0 | H6: 3 | I6: -3 | J6: -26 | K6: -3.67 | L6: -0.27 | M6: 3 | N6: 10 | O6: -1 | P6: 3 | Q6: 0 | R6: 40 | S6: 14 | T6: 188.18 | U6: 191.85 | V6: 27.23 | W6: 27.5 | X6: 7 | Y6: 4 | Z6: 10 | AA6: 0 | AB6: UEFA | AC6: CONCACAF | AD6: 6 | AE6: 6
A7: 6 | B7: Group stage | C7: A | D7: 2026-06-24 | E7: South Africa | F7: South Korea | G7: 1 | H7: 0 | I7: 1 | J7: -35 | K7: -89.8 | L7: -1.11 | M7: -3 | N7: -7 | O7: 0 | P7: 2 | Q7: 0 | R7: 60 | S7: 25 | T7: 49.25 | U7: 139.05 | V7: 26.35 | W7: 27.46 | X7: 2 | Y7: 5 | Z7: 6 | AA7: 13 | AB7: CAF | AC7: AFC | AD7: 6 | AE7: 6
A8: 7 | B8: Group stage | C8: B | D8: 2026-06-12 | E8: Canada | F8: Bosnia and Herzegovina | G8: 1 | H8: 1 | I8: 0 | J8: 34 | K8: 52.25 | L8: 0.5 | M8: 0 | N8: -10 | O8: 1 | P8: -3 | Q8: 0 | R8: 30 | S8: 64 | T8: 198.65 | U8: 146.4 | V8: 26.42 | W8: 25.92 | X8: 2 | Y8: 2 | Z8: 0 | AA8: 10 | AB8: CONCACAF | AC8: UEFA | AD8: 14 | AE8: 14
A9: 8 | B9: Group stage | C9: B | D9: 2026-06-13 | E9: Qatar | F9: Switzerland | G9: 1 | H9: 1 | I9: 0 | J9: -37 | K9: -312.57 | L9: 1.11 | M9: -2 | N9: -18 | O9: 0 | P9: -4 | Q9: 0 | R9: 56 | S9: 19 | T9: 19.93 | U9: 332.5 | V9: 28.92 | W9: 27.81 | X9: 2 | Y9: 4 | Z9: -6 | AA9: 12 | AB9: AFC | AC9: UEFA | AD9: 14 | AE9: 14
A10: 9 | B10: Group stage | C10: B | D10: 2026-06-18 | E10: Switzerland | F10: Bosnia and Herzegovina | G10: 4 | H10: 1 | I10: 3 | J10: 45 | K10: 186.1 | L10: 1.89 | M10: 2 | N10: 2 | O10: 0 | P10: 0 | Q10: -1 | R10: 19 | S10: 64 | T10: 332.5 | U10: 146.4 | V10: 27.81 | W10: 25.92 | X10: 4 | Y10: 2 | Z10: 12 | AA10: 10 | AB10: UEFA | AC10: UEFA | AD10: 5 | AE10: 6
A11: 10 | B11: Group stage | C11: B | D11: 2026-06-19 | E11: Canada | F11: Qatar | G11: 6 | H11: 0 | I11: 6 | J11: 26 | K11: 178.72 | L11: -2.5 | M11: 0 | N11: 6 | O11: 1 | P11: 1 | Q11: 1 | R11: 30 | S11: 56 | T11: 198.65 | U11: 19.93 | V11: 26.42 | W11: 28.92 | X11: 2 | Y11: 2 | Z11: 0 | AA11: -6 | AB11: CONCACAF | AC11: AFC | AD11: 7 | AE11: 6
A12: 11 | B12: Group stage | C12: B | D12: 2026-06-24 | E12: Switzerland | F12: Canada | G12: 2 | H12: 1 | I12: 1 | J12: 11 | K12: 133.85 | L12: 1.39 | M12: 2 | N12: 12 | O12: -1 | P12: 3 | Q12: 1 | R12: 19 | S12: 30 | T12: 332.5 | U12: 198.65 | V12: 27.81 | W12: 26.42 | X12: 4 | Y12: 2 | Z12: 12 | AA12: 0 | AB12: UEFA | AC12: CONCACAF | AD12: 6 | AE12: 5
A13: 12 | B13: Group stage | C13: B | D13: 2026-06-24 | E13: Bosnia and Herzegovina | F13: Qatar | G13: 3 | H13: 1 | I13: 2 | J13: -8 | K13: 126.47 | L13: -3 | M13: 0 | N13: 16 | O13: 0 | P13: 4 | Q13: 1 | R13: 64 | S13: 56 | T13: 146.4 | U13: 19.93 | V13: 25.92 | W13: 28.92 | X13: 2 | Y13: 2 | Z13: 10 | AA13: -6 | AB13: UEFA | AC13: AFC | AD13: 6 | AE13: 5
... A105: 104 | B105: Final | C105: - | D105: 2026-07-19 | E105: Spain | F105: Argentina | G105: 1 | H105: 0 | I105: 1 | J105: -1 | K105: 412.5 | L105: -2.43 | M105: 0 | N105: -2 | O105: 0 | P105: 1 | Q105: 1 | R105: 2 | S105: 1 | T105: 1220 | U105: 807.5 | V105: 26.19 | W105: 28.62 | X105: 8 | Y105: 8 | Z105: 19 | AA105: 21 | AB105: UEFA | AC105: CONMEBOL | AD105: 5 | AE105: 4

Sheet LR2.1 Feature Documentation
A1: LR 2.1 — Goal Difference Regression: Feature Documentation
A3: Feature | B3: Definition | C3: Construction (Home − Away) | D3: Data Source | E3: Assumption / Limitation
A4: Target: Goal Difference | B4: Home team's goals minus away team's goals in that match | C4: Home Score − Away Score | D4: FBref (knockout) + Wikipedia group pages, independently verified match-by-match | E4: Positive = home team won by more goals; negative = away team won by more
A5: X1 — FIFA Ranking Diff | B5: Difference in official FIFA World Ranking position | C5: Away Rank − Home Rank (so + favors home, since lower rank number = stronger team) | D5: FIFA.com ranking as of 11 June 2026, cross-validated across 3 independent news sources (MLSsoccer, ESPN Africa, The Peninsula Qatar) | E5: Exact FIFA ranking POINTS could not be reliably confirmed for most teams (FIFA's own site is JS-rendered and secondary sources disagreed); rank POSITION was used instead and is reliable for all 48 teams. VERIFIED: matches FIFA's own 11 Jun 2026 release (Argentina 1st, Spain 2nd, France 3rd). Sofascore team pages were rejected because they show live post-tournament rankings, which would leak match outcomes.
A6: X2 — Squad Market Value Diff | B6: Difference in total squad market value (EUR millions) | C6: Home Value − Away Value | D6: Transfermarkt data via Planet Football's 2026 World Cup squad value rankings | E6: Sourced from a secondary aggregator citing Transfermarkt (direct Transfermarkt access was blocked in the research environment). Recommend spot-checking 3-5 team values directly on Transfermarkt.com before final submission. TIMING CHECK: the earliest dated article found is 16 Jun 2026 (5 days after kick-off); identical values appear in articles dated 16 Jun, 18 Jun, 15 Jul and 28 Jul 2026, so the figures were not updated by match results (a static squad snapshot). A value taken strictly before 11 Jun could not be located, so a small timing risk remains and should be stated as a limitation.
A7: X3 — Squad Average Age Diff | B7: Difference in average age of the 26-man World Cup squad | C7: Home Age − Away Age | D7: Journalist compilations (RotoWire, cross-checked with CBS Sports) from official FIFA 26-man rosters announced 2 June 2026 | E7: A second independent source showed differing decimal values for a few teams (e.g. Ecuador); the CBS Sports-corroborated set was used. Minor (<1 year) imprecision possible for individual teams.
A8: X4 — Prior World Cup Best Result Diff | B8: Difference in each team's best-ever World Cup finish before 2026, coded ordinally (Winner=8 ... Never qualified=1) | C8: Home ordinal score − Away ordinal score | D8: Football history / FIFA World Cup records; Czechia credited with Czechoslovakia's results, Germany with West Germany's, DR Congo with Zaire's 1974 appearance | E8: Ordinal coding is a simplification (e.g. the real competitive gap between 'Winner' and 'Runner-up' may not be linear) — reasonable for a first-pass linear model but worth flagging as a limitation in the report.
A9: X5 — Qualifying Campaign GD Diff | B9: Difference in goal difference (GF-GA) during 2026 WC qualifying (2023-2025) | C9: Home Qualifying GD − Away Qualifying GD | D9: Wikipedia confederation qualification articles (UEFA/CONMEBOL/CAF/AFC/CONCACAF/OFC final group standings) | E9: Mexico, USA and Canada qualified automatically as hosts and played no qualifying campaign; their qualifying GD was set to 0 (neutral) rather than left blank, since this is a pre-match feature used in every one of their matches. This is a documented simplifying assumption, not a researched value.
A10: X6 — Host Advantage Diff | B10: Whether a team is one of the three co-host nations (USA, Mexico, Canada), who play all/most matches on home soil | C10: (1 if Home is host else 0) − (1 if Away is host else 0) → range {-1, 0, 1} | D10: 2026 FIFA World Cup hosting agreement (fixed tournament fact) | E10: Only hosts get true home-soil advantage; the Home/Away labels in the fixture list itself do not imply home advantage for non-host teams (all other matches are at neutral venues). 15 of 104 matches involve a host.
A11: X7 — Confederation Strength Diff | B11: Difference in an ordinal confederation strength tier (UEFA=6, CONMEBOL=5, CAF=4, CONCACAF=3, AFC=2, OFC=1) | C11: Home tier − Away tier | D11: Author-assigned ordinal ranking based on historical World Cup results by confederation (UEFA/CONMEBOL have combined 22 titles; CAF/CONCACAF have reached semifinals; AFC's best is 4th place; OFC has never passed the group stage) | E11: This index is a judgment call, not an official FIFA metric — state this explicitly in the report's methodology section and be ready to justify the ordering if asked.
A12: X8 — Rest Days Diff | B12: Difference in days of rest since each team's previous match in this World Cup | C12: Home Rest Days − Away Rest Days | D12: Computed directly from the verified 104-match schedule (date arithmetic) | E12: A team's very first match of the tournament has no prior match to measure from; a fixed baseline of 14 days (standard pre-tournament training-camp period) was assumed for all opening matches.

Sheet Variable Justification
A1: Variable | B1: Name | C1: Reason | D1: Expected effect on Goal Difference | E1: Source
A2: X1 | B2: FIFA Ranking Difference (Away rank - Home rank) | C2: Official summary of recent results and opponent strength; better-ranked teams should outscore weaker ones. | D2: + | E2: FIFA Men's World Ranking, 11 Jun 2026 (inside.fifa.com; cross-checked with MLSsoccer, ESPN)
A3: X2 | B3: Squad Market Value Difference (EUR m, Home - Away) | C3: Market value prices individual quality and depth; richer squads should win by more. | D3: + | E3: Transfermarkt values via Planet Football (values identical in articles dated 16 Jun, 18 Jun, 15 Jul, 28 Jul 2026)
A4: X3 | B4: Squad Average Age Difference (years, Home - Away) | C4: Older squads bring experience but lose pace and stamina; effect direction is ambiguous, so no strong prior. | D4: +/- (unclear) | E4: Official 26-man FIFA squads announced 2 Jun 2026 (RotoWire, CBS Sports)
A5: X4 | B5: Prior World Cup Best Result Difference (ordinal 1-8) | C5: Tournament pedigree reflects football culture and big-match experience. | D5: + | E5: FIFA World Cup records (Czechoslovakia->Czechia, West Germany->Germany, Zaire->DR Congo)
A6: X5 | B6: Qualifying Goal Difference (Home - Away) | C6: Goal difference over 2023-25 qualifiers is a pre-tournament proxy for attacking and defensive form. | D6: + | E6: Wikipedia 2026 FIFA World Cup qualification pages (all confederations); hosts set to 0 (assumption)
A7: X6 | B7: Host Advantage Difference (1 / 0 / -1) | C7: Hosts play on home soil with crowd support and no travel. | D7: + | E7: Tournament hosting arrangement: USA, Mexico, Canada
A8: X7 | B8: Confederation Strength Difference (tier 1-6) | C8: Teams from stronger confederations face tougher competition and tend to perform better at World Cups. | D8: + | E8: Author-assigned ordinal tier from historical World Cup results (not an official metric)
A9: X8 | B9: Rest Days Difference (Home - Away) | C9: More recovery time between matches should reduce fatigue and injury risk. | D9: + (weak) | E9: Computed from the verified match schedule; opening matches assumed 14 days

Sheet Inferential Tests
A1: Var | B1: Feature | C1: Pearson r | D1: CI95 low | E1: CI95 high | F1: p (Pearson) | G1: Spearman rho | H1: p (Spearman)
A2: X1 | B2: X1 FIFA Rank Diff (Away-Home) | C2: 0.605 | D2: 0.467 | E2: 0.715 | F2: 0 | G2: 0.564 | H2: 0
A3: X2 | B3: X2 Squad Value Diff EURm (Home-Away) | C3: 0.544 | D3: 0.393 | E3: 0.667 | F3: 0 | G3: 0.553 | H3: 0
A4: X3 | B4: X3 Squad Age Diff (Home-Away) | C4: -0.079 | D4: -0.267 | E4: 0.116 | F4: 0.42722 | G4: -0.055 | H4: 0.58124
A5: X4 | B5: X4 Prior WC Best Result Diff (Home-Away) | C5: 0.48 | D5: 0.316 | E5: 0.616 | F5: 0 | G5: 0.465 | H5: 0
A6: X5 | B6: X5 Qualifying GD Diff (Home-Away) | C6: 0.292 | D6: 0.106 | E6: 0.459 | F6: 0.00262 | G6: 0.312 | H6: 0.00126
A7: X6 | B7: X6 Host Advantage Diff (Home-Away) | C7: 0.141 | D7: -0.053 | E7: 0.324 | F7: 0.15431 | G7: 0.125 | H7: 0.20485
A8: X7 | B8: X7 Confederation Strength Diff (Home-Away) | C8: 0.352 | D8: 0.171 | E8: 0.51 | F8: 0.00024 | G8: 0.27 | H8: 0.00556
A9: X8 | B9: X8 Rest Days Diff (Home-Away) | C9: 0.189 | D9: -0.003 | E9: 0.368 | F9: 0.05429 | G9: 0.199 | H9: 0.0429
A12: Host vs non-host: 15 host matches, mean host-perspective goal difference +0.87; one-sample t-test vs 0: t=1.39, p=0.187. Welch t-test vs the 89 non-host matches: t=0.28, p=0.785. No significant host effect.
A13: OLS GD ~ FIFA rank diff + host: rank coefficient +0.034 per place (p<0.001); host coefficient +0.27 (95% CI -0.53 to 1.06, p=0.50) after controlling for strength.
A14: Mean goal difference across all 104 matches is +0.83 (one-sample t-test p<0.001), because stronger or seeded teams are listed as Home more often.
A15: Significant at 5%: X1, X2, X4, X5, X7 (Pearson and Spearman agree). Not significant: X3, X6; X8 is borderline (Pearson p=0.054, Spearman p=0.043).

Sheet Data Dictionary
A1: Column | B1: Type | C1: Description | D1: Source
A2: Match # | B2: int | C2: Row ID 1-104 in chronological order of listing | D2: Wikipedia/FBref
A3: Stage | B3: text | C3: Group stage, Round of 32, Round of 16, Quarter-final, Semi-final, Third-place match, Final | D3: FBref
A4: Group | B4: text | C4: Group letter A-L for group stage; blank for knockouts | D4: Wikipedia
A5: Date | B5: date | C5: Match date (YYYY-MM-DD) | D5: Wikipedia/FBref
A6: Home / Away | B6: text | C6: Team listed first / second in the fixture. Not a true home advantage (except hosts) | D6: Wikipedia/FBref
A7: Home Score / Away Score | B7: int | C7: Goals after normal time and extra time; shoot-out goals excluded | D7: Wikipedia/FBref
A8: Goal Difference (Target) | B8: int | C8: Home Score - Away Score; range -4 to +6 | D8: Computed
A9: X1..X8 | B9: numeric | C9: Feature differences, see variable_justification.csv for meaning, expected sign and source | D9: See justification
A10: Home/Away raw columns | B10: numeric/text | C10: Underlying team-level values behind each feature, kept for transparency and for building LR 2.2 | D10: team_level_data_48.csv

Sheet Team-Level Data (48)
A1: Team | B1: Confederation | C1: Confederation_Tier | D1: FIFA_Rank_11Jun2026 | E1: Squad_Value_EURm | F1: Squad_Avg_Age | G1: Prior_WC_Best_Category | H1: Prior_WC_Best_Ordinal | I1: Qualifying_GD | J1: Is_Host
A2: Argentina | B2: CONMEBOL | C2: 5 | D2: 1 | E2: 807.5 | F2: 28.62 | G2: Winner | H2: 8 | I2: 21 | J2: 0
A3: Spain | B3: UEFA | C3: 6 | D3: 2 | E3: 1220 | F3: 26.19 | G3: Winner | H3: 8 | I3: 19 | J3: 0
A4: France | B4: UEFA | C4: 6 | D4: 3 | E4: 1520 | F4: 26.58 | G4: Winner | H4: 8 | I4: 12 | J4: 0
A5: England | B5: UEFA | C5: 6 | D5: 4 | E5: 1360 | F5: 26.62 | G5: Winner | H5: 8 | I5: 22 | J5: 0
A6: Portugal | B6: UEFA | C6: 6 | D6: 5 | E6: 1010 | F6: 27.54 | G6: Third place | H6: 6 | I6: 13 | J6: 0
A7: Brazil | B7: CONMEBOL | C7: 5 | D7: 6 | E7: 928.2 | F7: 28.65 | G7: Winner | H7: 8 | I7: 7 | J7: 0
A8: Morocco | B8: CAF | C8: 4 | D8: 7 | E8: 447.7 | F8: 25.92 | G8: Fourth place | H8: 5 | I8: 20 | J8: 0
A9: Netherlands | B9: UEFA | C9: 6 | D9: 8 | E9: 754.2 | F9: 27.27 | G9: Runner-up | H9: 7 | I9: 23 | J9: 0
A10: Belgium | B10: UEFA | C10: 6 | D10: 9 | E10: 547.5 | F10: 27.12 | G10: Third place | H10: 6 | I10: 22 | J10: 0
A11: Germany | B11: UEFA | C11: 6 | D11: 10 | E11: 947 | F11: 27.54 | G11: Winner | H11: 8 | I11: 13 | J11: 0
A12: Croatia | B12: UEFA | C12: 6 | D12: 11 | E12: 387.3 | F12: 27.88 | G12: Runner-up | H12: 7 | I12: 22 | J12: 0
A13: Colombia | B13: CONMEBOL | C13: 5 | D13: 13 | E13: 302.35 | F13: 29.58 | G13: Quarter-final | H13: 4 | I13: 10 | J13: 0
... A49: New Zealand | B49: OFC | C49: 1 | D49: 85 | E49: 34.45 | F49: 27.62 | G49: Group stage | H49: 2 | I49: 18 | J49: 0

Sheet LR2.1 EDA
A1: LR 2.1 — Exploratory Data Analysis
A2: 104 matches, 2026 FIFA World Cup — target: Goal Difference, 8 pre-match features
A4: Key findings
A5: • Missing values: none — all 104 rows x 8 features are fully populated (0 NA anywhere).
A6: • Target (Goal Difference) is NOT normally distributed (Shapiro-Wilk W=0.956, p=0.0015) — expected, since it's a bounded integer count with a floor near 0 (most matches are close, few are routs). Flag this in the report if the group plans an OLS-assumptions discussion.
A7: • Strongest single predictors of Goal Difference: X1 FIFA Rank Diff (r=+0.61), X2 Squad Value Diff (r=+0.54), X4 Prior WC Best Result Diff (r=+0.48). These three all point the same direction: a 'stronger team' signal.
A8: • Weakest predictors: X3 Squad Age Diff (r=-0.08, essentially no linear relationship) and X6 Host Advantage (r=+0.14, only 3 host teams in the data so limited variation).
A9: • Multicollinearity flag: X1 (FIFA Rank), X2 (Squad Value) and X4 (Prior WC Best) are all moderately-to-strongly correlated with each other (r=0.67-0.80) — they're all proxies for the same underlying 'team strength' concept. VIF for all three is still under 5 (acceptable), but this is worth naming explicitly in the report's limitations section.
A10: • X6 Host Advantage: only 15 of 104 matches involve a host (USA, Mexico or Canada), and the host effect is not statistically significant (r=+0.14, p=0.15; host-perspective mean goal difference +0.87, one-sample t-test p=0.19). Keep it on theoretical grounds but report it as an imprecise estimate.
A11: • Home/Away slot is not a true home advantage: the mean goal difference across all matches is +0.83 (p<0.001) because stronger or seeded teams tend to be listed first (mean X1 rank difference = +8.9). Expect a positive intercept in the models and explain this in the report.
A13: Descriptive statistics
A14: Variable | B14: count | C14: mean | D14: std | E14: min | F14: 25% | G14: 50% | H14: 75% | I14: max | J14: skew
A15: Goal Difference (Target) | B15: 104 | C15: 0.83 | D15: 1.91 | E15: -4 | F15: 0 | G15: 1 | H15: 2 | I15: 6 | J15: 0
A16: X1 FIFA Rank Diff (Away-Home) | B16: 104 | C16: 8.88 | D16: 33.23 | E16: -76 | F16: -10.75 | G16: 8.5 | H16: 30 | I16: 77 | J16: -0.03
A17: X2 Squad Value Diff EURm (Home-Away) | B17: 104 | C17: 183.77 | D17: 552.68 | E17: -1325.45 | F17: -141.42 | G17: 146 | H17: 481.21 | I17: 1498.8 | J17: 0.06
A18: X3 Squad Age Diff (Home-Away) | B18: 104 | C18: -0.01 | D18: 1.49 | E18: -3.58 | F18: -1.11 | G18: 0.02 | H18: 1.02 | I18: 3.38 | J18: -0.02
A19: X4 Prior WC Best Result Diff (Home-Away) | B19: 104 | C19: 0.97 | D19: 3.42 | E19: -7 | F19: -1 | G19: 1 | H19: 4 | I19: 7 | J19: -0.25
A20: X5 Qualifying GD Diff (Home-Away) | B20: 104 | C20: 1.31 | D20: 11.35 | E20: -28 | F20: -7 | G20: 2 | H20: 8 | I20: 32 | J20: 0.11
A21: X6 Host Advantage Diff (Home-Away) | B21: 104 | C21: 0.03 | D21: 0.38 | E21: -1 | F21: 0 | G21: 0 | H21: 0 | I21: 1 | J21: 0.31
A22: X7 Confederation Strength Diff (Home-Away) | B22: 104 | C22: 0.45 | D22: 2.21 | E22: -5 | F22: -1 | G22: 1 | H22: 2 | I22: 4 | J22: -0.51
A23: X8 Rest Days Diff (Home-Away) | B23: 104 | C23: -0.09 | D23: 0.76 | E23: -2 | F23: 0 | G23: 0 | H23: 0 | I23: 3 | J23: 0.41
A25: Charts
